# 异常处理

三种

- error接口
- panic
- recover

不太致命的错误可以使用 `error` 接口返回错误信息



## panic

致命错误会直接导致程序崩溃，此时系统会自动调用 `panic` 函数

- 数组越界
- 空指针引用

可以手动调用 `panic` 函数，触发程序异常退出


```go
package main

import (
    "fmt"
)


func testa(){
    fmt.Println("aaaaaaaaaaa")
}

// 手动触发异常
func testb(){
    fmt.Println("bbbbbbbbbbb")
    panic("testb 异常")
}

// 系统触发异常
func testc(x int){
    var a [10]int
    a[x] = 11
    fmt.Println("ccccccccccc")
}

func main(){
    testa()
    //testb()
    testc(11)
}
```


## recover

用于拦截panic，让程序从崩溃中回来

`recover` 只有在 `defer` 调用的函数中有效



例子：

```go
package main

import (
    "fmt"
)

func testa () {
    fmt.Println("aaaaaaaaaaa")
}

func testb (x int) {
    // 恢复程序运行状态，返回错误值
    defer func(){
        if err :=recover(); err != nil {
            fmt.Println(err)
        }
    }()
    var a [10]int
    a[x] = 11
    fmt.Println("bbbbbbbbbbb")
}

func testc () {
    fmt.Println("ccccccccccc")
}

func main () {
    testa()
    testb(1)
    testb(11)
    testc()
}
```
